Dataset not found: 404 GET https://bigquery.googleapis.com/bigquery/v2/projects/function-project-423615/datasets/VMO2_Dataset?prettyPrint=false: Not found: Dataset function-project-423615:VMO2_Dataset
Traceback (most recent call last):
  File "C:\Users\ConorLynam\Coding\VMO2 Onboarding Project\app.py", line 137, in <module>
    client.get_dataset(dataset_id)
  File "C:\Users\ConorLynam\Coding\VMO2 Onboarding Project\venv\Lib\site-packages\google\cloud\bigquery\client.py", line 870, in get_dataset
    api_response = self._call_api(
                   ^^^^^^^^^^^^^^^
  File "C:\Users\ConorLynam\Coding\VMO2 Onboarding Project\venv\Lib\site-packages\google\cloud\bigquery\client.py", line 833, in _call_api
    return call()
           ^^^^^^
  File "C:\Users\ConorLynam\Coding\VMO2 Onboarding Project\venv\Lib\site-packages\google\api_core\retry\retry_unary.py", line 293, in retry_wrapped_func
    return retry_target(
           ^^^^^^^^^^^^^
  File "C:\Users\ConorLynam\Coding\VMO2 Onboarding Project\venv\Lib\site-packages\google\api_core\retry\retry_unary.py", line 153, in retry_target
    _retry_error_helper(
  File "C:\Users\ConorLynam\Coding\VMO2 Onboarding Project\venv\Lib\site-packages\google\api_core\retry\retry_base.py", line 212, in _retry_error_helper
    raise final_exc from source_exc
  File "C:\Users\ConorLynam\Coding\VMO2 Onboarding Project\venv\Lib\site-packages\google\api_core\retry\retry_unary.py", line 144, in retry_target
    result = target()
             ^^^^^^^^
  File "C:\Users\ConorLynam\Coding\VMO2 Onboarding Project\venv\Lib\site-packages\google\cloud\_http\__init__.py", line 494, in api_request
    raise exceptions.from_http_response(response)
google.api_core.exceptions.NotFound: 404 GET https://bigquery.googleapis.com/bigquery/v2/projects/function-project-423615/datasets/VMO2_Dataset?prettyPrint=false: Not found: Dataset function-project-423615:VMO2_Dataset
Failed to create dataset: 403 POST https://bigquery.googleapis.com/bigquery/v2/projects/function-project-423615/datasets?prettyPrint=false: Access Denied: Project function-project-423615: User does not have bigquery.datasets.create permission in project function-project-423615.
Traceback (most recent call last):
  File "C:\Users\ConorLynam\Coding\VMO2 Onboarding Project\app.py", line 143, in <module>
    client.create_dataset(dataset_id)
  File "C:\Users\ConorLynam\Coding\VMO2 Onboarding Project\venv\Lib\site-packages\google\cloud\bigquery\client.py", line 683, in create_dataset
    api_response = self._call_api(
                   ^^^^^^^^^^^^^^^
  File "C:\Users\ConorLynam\Coding\VMO2 Onboarding Project\venv\Lib\site-packages\google\cloud\bigquery\client.py", line 833, in _call_api
    return call()
           ^^^^^^
  File "C:\Users\ConorLynam\Coding\VMO2 Onboarding Project\venv\Lib\site-packages\google\api_core\retry\retry_unary.py", line 293, in retry_wrapped_func
    return retry_target(
           ^^^^^^^^^^^^^
  File "C:\Users\ConorLynam\Coding\VMO2 Onboarding Project\venv\Lib\site-packages\google\api_core\retry\retry_unary.py", line 153, in retry_target
    _retry_error_helper(
  File "C:\Users\ConorLynam\Coding\VMO2 Onboarding Project\venv\Lib\site-packages\google\api_core\retry\retry_base.py", line 212, in _retry_error_helper
    raise final_exc from source_exc
  File "C:\Users\ConorLynam\Coding\VMO2 Onboarding Project\venv\Lib\site-packages\google\api_core\retry\retry_unary.py", line 144, in retry_target
    result = target()
             ^^^^^^^^
  File "C:\Users\ConorLynam\Coding\VMO2 Onboarding Project\venv\Lib\site-packages\google\cloud\_http\__init__.py", line 494, in api_request
    raise exceptions.from_http_response(response)
google.api_core.exceptions.Forbidden: 403 POST https://bigquery.googleapis.com/bigquery/v2/projects/function-project-423615/datasets?prettyPrint=false: Access Denied: Project function-project-423615: User does not have bigquery.datasets.create permission in project function-project-423615.
Failed to create dataset: 403 POST https://bigquery.googleapis.com/bigquery/v2/projects/function-project-423615/datasets?prettyPrint=false: Access Denied: Project function-project-423615: User does not have bigquery.datasets.create permission in project function-project-423615.
Traceback (most recent call last):
  File "C:\Users\ConorLynam\Coding\VMO2 Onboarding Project\app.py", line 143, in <module>
    client.create_dataset(dataset_id)
  File "C:\Users\ConorLynam\Coding\VMO2 Onboarding Project\venv\Lib\site-packages\google\cloud\bigquery\client.py", line 683, in create_dataset
    api_response = self._call_api(
                   ^^^^^^^^^^^^^^^
  File "C:\Users\ConorLynam\Coding\VMO2 Onboarding Project\venv\Lib\site-packages\google\cloud\bigquery\client.py", line 833, in _call_api
    return call()
           ^^^^^^
  File "C:\Users\ConorLynam\Coding\VMO2 Onboarding Project\venv\Lib\site-packages\google\api_core\retry\retry_unary.py", line 293, in retry_wrapped_func
    return retry_target(
           ^^^^^^^^^^^^^
  File "C:\Users\ConorLynam\Coding\VMO2 Onboarding Project\venv\Lib\site-packages\google\api_core\retry\retry_unary.py", line 153, in retry_target
    _retry_error_helper(
  File "C:\Users\ConorLynam\Coding\VMO2 Onboarding Project\venv\Lib\site-packages\google\api_core\retry\retry_base.py", line 212, in _retry_error_helper
    raise final_exc from source_exc
  File "C:\Users\ConorLynam\Coding\VMO2 Onboarding Project\venv\Lib\site-packages\google\api_core\retry\retry_unary.py", line 144, in retry_target
    result = target()
             ^^^^^^^^
  File "C:\Users\ConorLynam\Coding\VMO2 Onboarding Project\venv\Lib\site-packages\google\cloud\_http\__init__.py", line 494, in api_request
    raise exceptions.from_http_response(response)
google.api_core.exceptions.Forbidden: 403 POST https://bigquery.googleapis.com/bigquery/v2/projects/function-project-423615/datasets?prettyPrint=false: Access Denied: Project function-project-423615: User does not have bigquery.datasets.create permission in project function-project-423615.
ValueError: Missing or invalid data: 0
Traceback (most recent call last):
  File "C:\Users\ConorLynam\Coding\VMO2 Onboarding Project\app.py", line 175, in get_weather_for_user
    raise ValueError(f'Missing or invalid data: {obj}')
ValueError: Missing or invalid data: 0
Unkown exception thrown when making API requset to Weather API:If using all scalar values, you must pass an index
Traceback (most recent call last):
  File "C:\Users\ConorLynam\Coding\VMO2 Onboarding Project\app.py", line 170, in get_weather_response
    create_csv_file(weather_data)
  File "C:\Users\ConorLynam\Coding\VMO2 Onboarding Project\app.py", line 56, in create_csv_file
    df = pd.DataFrame(flat_json)
         ^^^^^^^^^^^^^^^^^^^^^^^
  File "C:\Users\ConorLynam\Coding\VMO2 Onboarding Project\venv\Lib\site-packages\pandas\core\frame.py", line 778, in __init__
    mgr = dict_to_mgr(data, index, columns, dtype=dtype, copy=copy, typ=manager)
          ^^^^^^^^^^^^^^^^^^^^^^^^^^^^^^^^^^^^^^^^^^^^^^^^^^^^^^^^^^^^^^^^^^^^^^
  File "C:\Users\ConorLynam\Coding\VMO2 Onboarding Project\venv\Lib\site-packages\pandas\core\internals\construction.py", line 503, in dict_to_mgr
    return arrays_to_mgr(arrays, columns, index, dtype=dtype, typ=typ, consolidate=copy)
           ^^^^^^^^^^^^^^^^^^^^^^^^^^^^^^^^^^^^^^^^^^^^^^^^^^^^^^^^^^^^^^^^^^^^^^^^^^^^^
  File "C:\Users\ConorLynam\Coding\VMO2 Onboarding Project\venv\Lib\site-packages\pandas\core\internals\construction.py", line 114, in arrays_to_mgr
    index = _extract_index(arrays)
            ^^^^^^^^^^^^^^^^^^^^^^
  File "C:\Users\ConorLynam\Coding\VMO2 Onboarding Project\venv\Lib\site-packages\pandas\core\internals\construction.py", line 667, in _extract_index
    raise ValueError("If using all scalar values, you must pass an index")
ValueError: If using all scalar values, you must pass an index
Error creating csv file: If using all scalar values, you must pass an index
Traceback (most recent call last):
  File "C:\Users\ConorLynam\Coding\VMO2 Onboarding Project\app.py", line 171, in get_weather_response
    create_csv_file(weather_data)
  File "C:\Users\ConorLynam\Coding\VMO2 Onboarding Project\app.py", line 56, in create_csv_file
    df = pd.DataFrame(flat_json)
         ^^^^^^^^^^^^^^^^^^^^^^^
  File "C:\Users\ConorLynam\Coding\VMO2 Onboarding Project\venv\Lib\site-packages\pandas\core\frame.py", line 778, in __init__
    mgr = dict_to_mgr(data, index, columns, dtype=dtype, copy=copy, typ=manager)
          ^^^^^^^^^^^^^^^^^^^^^^^^^^^^^^^^^^^^^^^^^^^^^^^^^^^^^^^^^^^^^^^^^^^^^^
  File "C:\Users\ConorLynam\Coding\VMO2 Onboarding Project\venv\Lib\site-packages\pandas\core\internals\construction.py", line 503, in dict_to_mgr
    return arrays_to_mgr(arrays, columns, index, dtype=dtype, typ=typ, consolidate=copy)
           ^^^^^^^^^^^^^^^^^^^^^^^^^^^^^^^^^^^^^^^^^^^^^^^^^^^^^^^^^^^^^^^^^^^^^^^^^^^^^
  File "C:\Users\ConorLynam\Coding\VMO2 Onboarding Project\venv\Lib\site-packages\pandas\core\internals\construction.py", line 114, in arrays_to_mgr
    index = _extract_index(arrays)
            ^^^^^^^^^^^^^^^^^^^^^^
  File "C:\Users\ConorLynam\Coding\VMO2 Onboarding Project\venv\Lib\site-packages\pandas\core\internals\construction.py", line 667, in _extract_index
    raise ValueError("If using all scalar values, you must pass an index")
ValueError: If using all scalar values, you must pass an index
Error fetching location
Error sending data to BigQuery: send_data_to_bigquery() missing 1 required positional argument: 'data'
Traceback (most recent call last):
  File "C:\Users\ConorLynam\Coding\VMO2 Onboarding Project\app.py", line 201, in get_weather_response
    send_data_to_bigquery(data)
TypeError: send_data_to_bigquery() missing 1 required positional argument: 'data'
