Dataset not found: 404 GET https://bigquery.googleapis.com/bigquery/v2/projects/function-project-423615/datasets/VMO2%20Dataset?prettyPrint=false: Request couldn't be served.
Traceback (most recent call last):
  File "C:\Users\ConorLynam\Coding\VMO2 Onboarding Project\app.py", line 137, in <module>
    client.get_dataset(dataset_id)
  File "C:\Users\ConorLynam\Coding\VMO2 Onboarding Project\venv\Lib\site-packages\google\cloud\bigquery\client.py", line 870, in get_dataset
    api_response = self._call_api(
                   ^^^^^^^^^^^^^^^
  File "C:\Users\ConorLynam\Coding\VMO2 Onboarding Project\venv\Lib\site-packages\google\cloud\bigquery\client.py", line 833, in _call_api
    return call()
           ^^^^^^
  File "C:\Users\ConorLynam\Coding\VMO2 Onboarding Project\venv\Lib\site-packages\google\api_core\retry\retry_unary.py", line 293, in retry_wrapped_func
    return retry_target(
           ^^^^^^^^^^^^^
  File "C:\Users\ConorLynam\Coding\VMO2 Onboarding Project\venv\Lib\site-packages\google\api_core\retry\retry_unary.py", line 153, in retry_target
    _retry_error_helper(
  File "C:\Users\ConorLynam\Coding\VMO2 Onboarding Project\venv\Lib\site-packages\google\api_core\retry\retry_base.py", line 212, in _retry_error_helper
    raise final_exc from source_exc
  File "C:\Users\ConorLynam\Coding\VMO2 Onboarding Project\venv\Lib\site-packages\google\api_core\retry\retry_unary.py", line 144, in retry_target
    result = target()
             ^^^^^^^^
  File "C:\Users\ConorLynam\Coding\VMO2 Onboarding Project\venv\Lib\site-packages\google\cloud\_http\__init__.py", line 494, in api_request
    raise exceptions.from_http_response(response)
google.api_core.exceptions.NotFound: 404 GET https://bigquery.googleapis.com/bigquery/v2/projects/function-project-423615/datasets/VMO2%20Dataset?prettyPrint=false: Request couldn't be served.
Dataset not found: 404 GET https://bigquery.googleapis.com/bigquery/v2/projects/function-project-423615/datasets/VMO2%20Dataset?prettyPrint=false: Request couldn't be served.
Traceback (most recent call last):
  File "C:\Users\ConorLynam\Coding\VMO2 Onboarding Project\app.py", line 137, in <module>
    client.get_dataset(dataset_id)
  File "C:\Users\ConorLynam\Coding\VMO2 Onboarding Project\venv\Lib\site-packages\google\cloud\bigquery\client.py", line 870, in get_dataset
    api_response = self._call_api(
                   ^^^^^^^^^^^^^^^
  File "C:\Users\ConorLynam\Coding\VMO2 Onboarding Project\venv\Lib\site-packages\google\cloud\bigquery\client.py", line 833, in _call_api
    return call()
           ^^^^^^
  File "C:\Users\ConorLynam\Coding\VMO2 Onboarding Project\venv\Lib\site-packages\google\api_core\retry\retry_unary.py", line 293, in retry_wrapped_func
    return retry_target(
           ^^^^^^^^^^^^^
  File "C:\Users\ConorLynam\Coding\VMO2 Onboarding Project\venv\Lib\site-packages\google\api_core\retry\retry_unary.py", line 153, in retry_target
    _retry_error_helper(
  File "C:\Users\ConorLynam\Coding\VMO2 Onboarding Project\venv\Lib\site-packages\google\api_core\retry\retry_base.py", line 212, in _retry_error_helper
    raise final_exc from source_exc
  File "C:\Users\ConorLynam\Coding\VMO2 Onboarding Project\venv\Lib\site-packages\google\api_core\retry\retry_unary.py", line 144, in retry_target
    result = target()
             ^^^^^^^^
  File "C:\Users\ConorLynam\Coding\VMO2 Onboarding Project\venv\Lib\site-packages\google\cloud\_http\__init__.py", line 494, in api_request
    raise exceptions.from_http_response(response)
google.api_core.exceptions.NotFound: 404 GET https://bigquery.googleapis.com/bigquery/v2/projects/function-project-423615/datasets/VMO2%20Dataset?prettyPrint=false: Request couldn't be served.
Dataset not found: 404 GET https://bigquery.googleapis.com/bigquery/v2/projects/function-project-423615/datasets/VMO2%20Dataset?prettyPrint=false: Request couldn't be served.
Traceback (most recent call last):
  File "C:\Users\ConorLynam\Coding\VMO2 Onboarding Project\app.py", line 137, in <module>
    client.get_dataset(dataset_id)
  File "C:\Users\ConorLynam\Coding\VMO2 Onboarding Project\venv\Lib\site-packages\google\cloud\bigquery\client.py", line 870, in get_dataset
    api_response = self._call_api(
                   ^^^^^^^^^^^^^^^
  File "C:\Users\ConorLynam\Coding\VMO2 Onboarding Project\venv\Lib\site-packages\google\cloud\bigquery\client.py", line 833, in _call_api
    return call()
           ^^^^^^
  File "C:\Users\ConorLynam\Coding\VMO2 Onboarding Project\venv\Lib\site-packages\google\api_core\retry\retry_unary.py", line 293, in retry_wrapped_func
    return retry_target(
           ^^^^^^^^^^^^^
  File "C:\Users\ConorLynam\Coding\VMO2 Onboarding Project\venv\Lib\site-packages\google\api_core\retry\retry_unary.py", line 153, in retry_target
    _retry_error_helper(
  File "C:\Users\ConorLynam\Coding\VMO2 Onboarding Project\venv\Lib\site-packages\google\api_core\retry\retry_base.py", line 212, in _retry_error_helper
    raise final_exc from source_exc
  File "C:\Users\ConorLynam\Coding\VMO2 Onboarding Project\venv\Lib\site-packages\google\api_core\retry\retry_unary.py", line 144, in retry_target
    result = target()
             ^^^^^^^^
  File "C:\Users\ConorLynam\Coding\VMO2 Onboarding Project\venv\Lib\site-packages\google\cloud\_http\__init__.py", line 494, in api_request
    raise exceptions.from_http_response(response)
google.api_core.exceptions.NotFound: 404 GET https://bigquery.googleapis.com/bigquery/v2/projects/function-project-423615/datasets/VMO2%20Dataset?prettyPrint=false: Request couldn't be served.
Dataset not found: 404 GET https://bigquery.googleapis.com/bigquery/v2/projects/function-project-423615/datasets/VMO2%20Dataset?prettyPrint=false: Request couldn't be served.
Traceback (most recent call last):
  File "C:\Users\ConorLynam\Coding\VMO2 Onboarding Project\app.py", line 137, in <module>
    client.get_dataset(dataset_id)
  File "C:\Users\ConorLynam\Coding\VMO2 Onboarding Project\venv\Lib\site-packages\google\cloud\bigquery\client.py", line 870, in get_dataset
    api_response = self._call_api(
                   ^^^^^^^^^^^^^^^
  File "C:\Users\ConorLynam\Coding\VMO2 Onboarding Project\venv\Lib\site-packages\google\cloud\bigquery\client.py", line 833, in _call_api
    return call()
           ^^^^^^
  File "C:\Users\ConorLynam\Coding\VMO2 Onboarding Project\venv\Lib\site-packages\google\api_core\retry\retry_unary.py", line 293, in retry_wrapped_func
    return retry_target(
           ^^^^^^^^^^^^^
  File "C:\Users\ConorLynam\Coding\VMO2 Onboarding Project\venv\Lib\site-packages\google\api_core\retry\retry_unary.py", line 153, in retry_target
    _retry_error_helper(
  File "C:\Users\ConorLynam\Coding\VMO2 Onboarding Project\venv\Lib\site-packages\google\api_core\retry\retry_base.py", line 212, in _retry_error_helper
    raise final_exc from source_exc
  File "C:\Users\ConorLynam\Coding\VMO2 Onboarding Project\venv\Lib\site-packages\google\api_core\retry\retry_unary.py", line 144, in retry_target
    result = target()
             ^^^^^^^^
  File "C:\Users\ConorLynam\Coding\VMO2 Onboarding Project\venv\Lib\site-packages\google\cloud\_http\__init__.py", line 494, in api_request
    raise exceptions.from_http_response(response)
google.api_core.exceptions.NotFound: 404 GET https://bigquery.googleapis.com/bigquery/v2/projects/function-project-423615/datasets/VMO2%20Dataset?prettyPrint=false: Request couldn't be served.
Dataset not found: 404 GET https://bigquery.googleapis.com/bigquery/v2/projects/function-project-423615/datasets/VMO2_Dataset?prettyPrint=false: Not found: Dataset function-project-423615:VMO2_Dataset
Traceback (most recent call last):
  File "C:\Users\ConorLynam\Coding\VMO2 Onboarding Project\app.py", line 137, in <module>
    client.get_dataset(dataset_id)
  File "C:\Users\ConorLynam\Coding\VMO2 Onboarding Project\venv\Lib\site-packages\google\cloud\bigquery\client.py", line 870, in get_dataset
    api_response = self._call_api(
                   ^^^^^^^^^^^^^^^
  File "C:\Users\ConorLynam\Coding\VMO2 Onboarding Project\venv\Lib\site-packages\google\cloud\bigquery\client.py", line 833, in _call_api
    return call()
           ^^^^^^
  File "C:\Users\ConorLynam\Coding\VMO2 Onboarding Project\venv\Lib\site-packages\google\api_core\retry\retry_unary.py", line 293, in retry_wrapped_func
    return retry_target(
           ^^^^^^^^^^^^^
  File "C:\Users\ConorLynam\Coding\VMO2 Onboarding Project\venv\Lib\site-packages\google\api_core\retry\retry_unary.py", line 153, in retry_target
    _retry_error_helper(
  File "C:\Users\ConorLynam\Coding\VMO2 Onboarding Project\venv\Lib\site-packages\google\api_core\retry\retry_base.py", line 212, in _retry_error_helper
    raise final_exc from source_exc
  File "C:\Users\ConorLynam\Coding\VMO2 Onboarding Project\venv\Lib\site-packages\google\api_core\retry\retry_unary.py", line 144, in retry_target
    result = target()
             ^^^^^^^^
  File "C:\Users\ConorLynam\Coding\VMO2 Onboarding Project\venv\Lib\site-packages\google\cloud\_http\__init__.py", line 494, in api_request
    raise exceptions.from_http_response(response)
google.api_core.exceptions.NotFound: 404 GET https://bigquery.googleapis.com/bigquery/v2/projects/function-project-423615/datasets/VMO2_Dataset?prettyPrint=false: Not found: Dataset function-project-423615:VMO2_Dataset
